2021-04-13 14:13:42,393 INFO    MainThread:59 [wandb_setup.py:_flush():69] setting env: {}
2021-04-13 14:13:42,394 INFO    MainThread:59 [wandb_setup.py:_flush():69] setting login settings: {}
2021-04-13 14:13:42,394 INFO    MainThread:59 [wandb_setup.py:_flush():69] setting login settings: {'api_key': 'ada5925ed235ff6eb5aa559add19d37a21f5d86b'}
2021-04-13 14:13:42,395 INFO    MainThread:59 [wandb_init.py:_log_setup():336] Logging user logs to /gdrive/My Drive/To_GPU/wandb/run-20210413_141342-1o5m37fn/logs/debug.log
2021-04-13 14:13:42,395 INFO    MainThread:59 [wandb_init.py:_log_setup():337] Logging internal logs to /gdrive/My Drive/To_GPU/wandb/run-20210413_141342-1o5m37fn/logs/debug-internal.log
2021-04-13 14:13:42,396 INFO    MainThread:59 [wandb_init.py:init():369] calling init triggers
2021-04-13 14:13:42,397 INFO    MainThread:59 [wandb_init.py:init():376] wandb.init called with sweep_config: {}
config: {}
2021-04-13 14:13:42,397 INFO    MainThread:59 [wandb_init.py:init():391] re-initializing run, found existing run on stack: sycxf2wq
2021-04-13 14:13:42,401 INFO    MainThread:59 [wandb_run.py:finish():1167] finishing run ajsv/To_GPU/sycxf2wq
2021-04-13 14:13:42,436 INFO    MainThread:59 [jupyter.py:save_history():320] not saving jupyter history
2021-04-13 14:13:42,437 INFO    MainThread:59 [jupyter.py:save_ipynb():265] not saving jupyter notebook
2021-04-13 14:13:42,437 INFO    MainThread:59 [wandb_init.py:_jupyter_teardown():268] cleaning up jupyter logic
2021-04-13 14:13:42,437 INFO    MainThread:59 [wandb_run.py:_atexit_cleanup():1494] got exitcode: 0
2021-04-13 14:13:42,438 INFO    MainThread:59 [wandb_run.py:_restore():1466] restore
2021-04-13 14:13:42,450 INFO    MainThread:59 [wandb_run.py:_restore():1466] restore
2021-04-13 14:13:48,016 ERROR   MainThread:59 [wandb_run.py:_atexit_cleanup():1512] Problem finishing run
Traceback (most recent call last):
  File "/usr/local/lib/python3.7/dist-packages/wandb/sdk/wandb_run.py", line 1502, in _atexit_cleanup
    self._on_finish()
  File "/usr/local/lib/python3.7/dist-packages/wandb/sdk/wandb_run.py", line 1659, in _on_finish
    self._backend.interface.publish_telemetry(self._telemetry_obj)
  File "/usr/local/lib/python3.7/dist-packages/wandb/sdk/interface/interface.py", line 231, in publish_telemetry
    self._publish(rec)
  File "/usr/local/lib/python3.7/dist-packages/wandb/sdk/interface/interface.py", line 524, in _publish
    raise Exception("The wandb backend process has shutdown")
Exception: The wandb backend process has shutdown
2021-04-13 14:13:48,024 INFO    MainThread:59 [wandb_init.py:init():418] starting backend
2021-04-13 14:13:48,025 INFO    MainThread:59 [backend.py:_multiprocessing_setup():71] multiprocessing start_methods=fork,spawn,forkserver, using: spawn
2021-04-13 14:13:48,036 INFO    MainThread:59 [backend.py:ensure_launched():123] starting backend process...
2021-04-13 14:13:48,041 INFO    MainThread:59 [backend.py:ensure_launched():128] started backend process with pid: 1797
2021-04-13 14:13:48,043 INFO    MainThread:59 [wandb_init.py:init():423] backend started and connected
2021-04-13 14:13:48,101 INFO    MainThread:59 [wandb_init.py:init():463] updated telemetry
2021-04-13 14:13:48,103 INFO    MainThread:59 [wandb_init.py:init():482] communicating current version
2021-04-13 14:13:48,811 INFO    MainThread:59 [wandb_init.py:init():487] got version response 
2021-04-13 14:13:48,811 INFO    MainThread:59 [wandb_init.py:init():495] communicating run to backend with 30 second timeout
2021-04-13 14:13:48,966 INFO    MainThread:59 [wandb_init.py:init():520] starting run threads in backend
2021-04-13 14:13:50,620 INFO    MainThread:59 [wandb_run.py:_console_start():1524] atexit reg
2021-04-13 14:13:50,627 INFO    MainThread:59 [wandb_run.py:_redirect():1371] redirect: SettingsConsole.WRAP
2021-04-13 14:13:50,628 INFO    MainThread:59 [wandb_run.py:_redirect():1414] Wrapping output streams.
2021-04-13 14:13:50,628 INFO    MainThread:59 [wandb_run.py:_redirect():1438] Redirects installed.
2021-04-13 14:13:50,628 INFO    MainThread:59 [wandb_init.py:init():544] run started, returning control to user process
